2022-05-02 09:32:07,308, WARNING Invalid HTTP request received.
Traceback (most recent call last):
  File "/data1/work/.conda/envs/nlp/lib/python3.8/site-packages/uvicorn/protocols/http/h11_impl.py", line 129, in handle_events
    event = self.conn.next_event()
  File "/data1/work/.conda/envs/nlp/lib/python3.8/site-packages/h11/_connection.py", line 443, in next_event
    exc._reraise_as_remote_protocol_error()
  File "/data1/work/.conda/envs/nlp/lib/python3.8/site-packages/h11/_util.py", line 76, in _reraise_as_remote_protocol_error
    raise self
  File "/data1/work/.conda/envs/nlp/lib/python3.8/site-packages/h11/_connection.py", line 425, in next_event
    event = self._extract_next_receive_event()
  File "/data1/work/.conda/envs/nlp/lib/python3.8/site-packages/h11/_connection.py", line 367, in _extract_next_receive_event
    event = self._reader(self._receive_buffer)
  File "/data1/work/.conda/envs/nlp/lib/python3.8/site-packages/h11/_readers.py", line 68, in maybe_read_from_IDLE_client
    raise LocalProtocolError("illegal request line")
h11._util.RemoteProtocolError: illegal request line
2022-05-02 11:01:16,343, WARNING Invalid HTTP request received.
Traceback (most recent call last):
  File "/data1/work/.conda/envs/nlp/lib/python3.8/site-packages/uvicorn/protocols/http/h11_impl.py", line 129, in handle_events
    event = self.conn.next_event()
  File "/data1/work/.conda/envs/nlp/lib/python3.8/site-packages/h11/_connection.py", line 443, in next_event
    exc._reraise_as_remote_protocol_error()
  File "/data1/work/.conda/envs/nlp/lib/python3.8/site-packages/h11/_util.py", line 76, in _reraise_as_remote_protocol_error
    raise self
  File "/data1/work/.conda/envs/nlp/lib/python3.8/site-packages/h11/_connection.py", line 425, in next_event
    event = self._extract_next_receive_event()
  File "/data1/work/.conda/envs/nlp/lib/python3.8/site-packages/h11/_connection.py", line 367, in _extract_next_receive_event
    event = self._reader(self._receive_buffer)
  File "/data1/work/.conda/envs/nlp/lib/python3.8/site-packages/h11/_readers.py", line 68, in maybe_read_from_IDLE_client
    raise LocalProtocolError("illegal request line")
h11._util.RemoteProtocolError: illegal request line
2022-05-02 17:14:49,237, WARNING Invalid HTTP request received.
Traceback (most recent call last):
  File "/data1/work/.conda/envs/nlp/lib/python3.8/site-packages/uvicorn/protocols/http/h11_impl.py", line 129, in handle_events
    event = self.conn.next_event()
  File "/data1/work/.conda/envs/nlp/lib/python3.8/site-packages/h11/_connection.py", line 443, in next_event
    exc._reraise_as_remote_protocol_error()
  File "/data1/work/.conda/envs/nlp/lib/python3.8/site-packages/h11/_util.py", line 76, in _reraise_as_remote_protocol_error
    raise self
  File "/data1/work/.conda/envs/nlp/lib/python3.8/site-packages/h11/_connection.py", line 425, in next_event
    event = self._extract_next_receive_event()
  File "/data1/work/.conda/envs/nlp/lib/python3.8/site-packages/h11/_connection.py", line 367, in _extract_next_receive_event
    event = self._reader(self._receive_buffer)
  File "/data1/work/.conda/envs/nlp/lib/python3.8/site-packages/h11/_readers.py", line 68, in maybe_read_from_IDLE_client
    raise LocalProtocolError("illegal request line")
h11._util.RemoteProtocolError: illegal request line
2022-05-02 21:44:33,046, DEBUG Starting new HTTP connection (1): 127.0.0.1:8080
2022-05-02 21:44:35,045, DEBUG http://127.0.0.1:8080 "POST /api/v0/generate HTTP/1.1" 200 170
2022-05-02 21:47:47,940, INFO Shutting down
2022-05-02 21:47:48,041, INFO Waiting for application shutdown.
2022-05-02 21:47:48,042, INFO Application shutdown complete.
2022-05-02 21:47:48,043, INFO Finished server process [2132858]
