2022-05-26 00:41:27,204, WARNING Invalid HTTP request received.
Traceback (most recent call last):
  File "/data1/work/.conda/envs/nlp/lib/python3.8/site-packages/uvicorn/protocols/http/httptools_impl.py", line 124, in data_received
    self.parser.feed_data(data)
  File "httptools/parser/parser.pyx", line 212, in httptools.parser.parser.HttpParser.feed_data
httptools.parser.errors.HttpParserInvalidMethodError: Invalid method encountered
2022-05-26 00:41:27,287, WARNING Invalid HTTP request received.
Traceback (most recent call last):
  File "/data1/work/.conda/envs/nlp/lib/python3.8/site-packages/uvicorn/protocols/http/httptools_impl.py", line 124, in data_received
    self.parser.feed_data(data)
  File "httptools/parser/parser.pyx", line 212, in httptools.parser.parser.HttpParser.feed_data
httptools.parser.errors.HttpParserInvalidMethodError: Invalid method encountered
2022-05-26 00:41:27,367, WARNING Invalid HTTP request received.
Traceback (most recent call last):
  File "/data1/work/.conda/envs/nlp/lib/python3.8/site-packages/uvicorn/protocols/http/httptools_impl.py", line 124, in data_received
    self.parser.feed_data(data)
  File "httptools/parser/parser.pyx", line 212, in httptools.parser.parser.HttpParser.feed_data
httptools.parser.errors.HttpParserInvalidMethodError: Invalid method encountered
2022-05-26 00:41:27,447, WARNING Invalid HTTP request received.
Traceback (most recent call last):
  File "/data1/work/.conda/envs/nlp/lib/python3.8/site-packages/uvicorn/protocols/http/httptools_impl.py", line 124, in data_received
    self.parser.feed_data(data)
  File "httptools/parser/parser.pyx", line 212, in httptools.parser.parser.HttpParser.feed_data
httptools.parser.errors.HttpParserInvalidMethodError: Invalid method encountered
2022-05-26 01:15:08,844, WARNING Invalid HTTP request received.
Traceback (most recent call last):
  File "/data1/work/.conda/envs/nlp/lib/python3.8/site-packages/uvicorn/protocols/http/httptools_impl.py", line 124, in data_received
    self.parser.feed_data(data)
  File "httptools/parser/parser.pyx", line 212, in httptools.parser.parser.HttpParser.feed_data
httptools.parser.errors.HttpParserInvalidMethodError: Invalid method encountered
2022-05-26 01:15:11,723, WARNING Invalid HTTP request received.
Traceback (most recent call last):
  File "/data1/work/.conda/envs/nlp/lib/python3.8/site-packages/uvicorn/protocols/http/httptools_impl.py", line 124, in data_received
    self.parser.feed_data(data)
  File "httptools/parser/parser.pyx", line 212, in httptools.parser.parser.HttpParser.feed_data
httptools.parser.errors.HttpParserInvalidMethodError: Invalid method encountered
2022-05-26 01:15:23,793, WARNING Invalid HTTP request received.
Traceback (most recent call last):
  File "/data1/work/.conda/envs/nlp/lib/python3.8/site-packages/uvicorn/protocols/http/httptools_impl.py", line 124, in data_received
    self.parser.feed_data(data)
  File "httptools/parser/parser.pyx", line 212, in httptools.parser.parser.HttpParser.feed_data
httptools.parser.errors.HttpParserInvalidMethodError: Invalid method encountered
2022-05-26 11:16:04,582, WARNING Invalid HTTP request received.
Traceback (most recent call last):
  File "/data1/work/.conda/envs/nlp/lib/python3.8/site-packages/uvicorn/protocols/http/httptools_impl.py", line 124, in data_received
    self.parser.feed_data(data)
  File "httptools/parser/parser.pyx", line 212, in httptools.parser.parser.HttpParser.feed_data
httptools.parser.errors.HttpParserInvalidMethodError: Invalid method encountered
2022-05-26 11:16:04,757, WARNING Invalid HTTP request received.
Traceback (most recent call last):
  File "/data1/work/.conda/envs/nlp/lib/python3.8/site-packages/uvicorn/protocols/http/httptools_impl.py", line 124, in data_received
    self.parser.feed_data(data)
  File "httptools/parser/parser.pyx", line 212, in httptools.parser.parser.HttpParser.feed_data
httptools.parser.errors.HttpParserInvalidMethodError: Invalid method encountered
2022-05-26 11:21:50,039, WARNING Invalid HTTP request received.
Traceback (most recent call last):
  File "/data1/work/.conda/envs/nlp/lib/python3.8/site-packages/uvicorn/protocols/http/httptools_impl.py", line 124, in data_received
    self.parser.feed_data(data)
  File "httptools/parser/parser.pyx", line 212, in httptools.parser.parser.HttpParser.feed_data
httptools.parser.errors.HttpParserInvalidMethodError: Invalid method encountered
2022-05-26 14:00:57,103, WARNING Invalid HTTP request received.
Traceback (most recent call last):
  File "/data1/work/.conda/envs/nlp/lib/python3.8/site-packages/uvicorn/protocols/http/httptools_impl.py", line 124, in data_received
    self.parser.feed_data(data)
  File "httptools/parser/parser.pyx", line 212, in httptools.parser.parser.HttpParser.feed_data
httptools.parser.errors.HttpParserInvalidMethodError: Invalid method encountered
2022-05-26 14:00:57,277, WARNING Invalid HTTP request received.
Traceback (most recent call last):
  File "/data1/work/.conda/envs/nlp/lib/python3.8/site-packages/uvicorn/protocols/http/httptools_impl.py", line 124, in data_received
    self.parser.feed_data(data)
  File "httptools/parser/parser.pyx", line 212, in httptools.parser.parser.HttpParser.feed_data
httptools.parser.errors.HttpParserInvalidMethodError: Invalid method encountered
2022-05-26 14:30:52,874, WARNING Invalid HTTP request received.
Traceback (most recent call last):
  File "/data1/work/.conda/envs/nlp/lib/python3.8/site-packages/uvicorn/protocols/http/httptools_impl.py", line 124, in data_received
    self.parser.feed_data(data)
  File "httptools/parser/parser.pyx", line 212, in httptools.parser.parser.HttpParser.feed_data
httptools.parser.errors.HttpParserInvalidMethodError: Invalid method encountered
2022-05-26 14:31:38,636, WARNING Invalid HTTP request received.
Traceback (most recent call last):
  File "/data1/work/.conda/envs/nlp/lib/python3.8/site-packages/uvicorn/protocols/http/httptools_impl.py", line 124, in data_received
    self.parser.feed_data(data)
  File "httptools/parser/parser.pyx", line 212, in httptools.parser.parser.HttpParser.feed_data
httptools.parser.errors.HttpParserInvalidMethodError: Invalid method encountered
2022-05-26 14:34:45,610, WARNING Invalid HTTP request received.
Traceback (most recent call last):
  File "/data1/work/.conda/envs/nlp/lib/python3.8/site-packages/uvicorn/protocols/http/httptools_impl.py", line 124, in data_received
    self.parser.feed_data(data)
  File "httptools/parser/parser.pyx", line 212, in httptools.parser.parser.HttpParser.feed_data
httptools.parser.errors.HttpParserInvalidMethodError: Invalid method encountered
2022-05-26 14:34:46,388, WARNING Invalid HTTP request received.
Traceback (most recent call last):
  File "/data1/work/.conda/envs/nlp/lib/python3.8/site-packages/uvicorn/protocols/http/httptools_impl.py", line 124, in data_received
    self.parser.feed_data(data)
  File "httptools/parser/parser.pyx", line 212, in httptools.parser.parser.HttpParser.feed_data
httptools.parser.errors.HttpParserInvalidMethodError: Invalid method encountered
2022-05-26 14:34:51,037, WARNING Invalid HTTP request received.
Traceback (most recent call last):
  File "/data1/work/.conda/envs/nlp/lib/python3.8/site-packages/uvicorn/protocols/http/httptools_impl.py", line 124, in data_received
    self.parser.feed_data(data)
  File "httptools/parser/parser.pyx", line 212, in httptools.parser.parser.HttpParser.feed_data
httptools.parser.errors.HttpParserInvalidMethodError: Invalid method encountered
2022-05-26 14:36:20,651, WARNING Invalid HTTP request received.
Traceback (most recent call last):
  File "/data1/work/.conda/envs/nlp/lib/python3.8/site-packages/uvicorn/protocols/http/httptools_impl.py", line 124, in data_received
    self.parser.feed_data(data)
  File "httptools/parser/parser.pyx", line 212, in httptools.parser.parser.HttpParser.feed_data
httptools.parser.errors.HttpParserInvalidMethodError: Invalid method encountered
2022-05-26 15:40:43,725, WARNING Invalid HTTP request received.
Traceback (most recent call last):
  File "/data1/work/.conda/envs/nlp/lib/python3.8/site-packages/uvicorn/protocols/http/httptools_impl.py", line 124, in data_received
    self.parser.feed_data(data)
  File "httptools/parser/parser.pyx", line 212, in httptools.parser.parser.HttpParser.feed_data
httptools.parser.errors.HttpParserInvalidMethodError: Invalid method encountered
2022-05-26 15:50:36,263, WARNING Invalid HTTP request received.
Traceback (most recent call last):
  File "/data1/work/.conda/envs/nlp/lib/python3.8/site-packages/uvicorn/protocols/http/httptools_impl.py", line 124, in data_received
    self.parser.feed_data(data)
  File "httptools/parser/parser.pyx", line 212, in httptools.parser.parser.HttpParser.feed_data
httptools.parser.errors.HttpParserInvalidMethodError: Invalid method encountered
2022-05-26 15:58:27,953, WARNING Invalid HTTP request received.
Traceback (most recent call last):
  File "/data1/work/.conda/envs/nlp/lib/python3.8/site-packages/uvicorn/protocols/http/httptools_impl.py", line 124, in data_received
    self.parser.feed_data(data)
  File "httptools/parser/parser.pyx", line 212, in httptools.parser.parser.HttpParser.feed_data
httptools.parser.errors.HttpParserInvalidMethodError: Invalid method encountered
2022-05-26 16:35:22,181, ERROR Exception in ASGI application
Traceback (most recent call last):
  File "/data1/work/.conda/envs/nlp/lib/python3.8/site-packages/uvicorn/protocols/http/httptools_impl.py", line 372, in run_asgi
    result = await app(self.scope, self.receive, self.send)
  File "/data1/work/.conda/envs/nlp/lib/python3.8/site-packages/uvicorn/middleware/proxy_headers.py", line 75, in __call__
    return await self.app(scope, receive, send)
  File "/data1/work/.conda/envs/nlp/lib/python3.8/site-packages/uvicorn/middleware/debug.py", line 96, in __call__
    raise exc from None
  File "/data1/work/.conda/envs/nlp/lib/python3.8/site-packages/uvicorn/middleware/debug.py", line 93, in __call__
    await self.app(scope, receive, inner_send)
  File "/data1/work/.conda/envs/nlp/lib/python3.8/site-packages/fastapi/applications.py", line 261, in __call__
    await super().__call__(scope, receive, send)
  File "/data1/work/.conda/envs/nlp/lib/python3.8/site-packages/starlette/applications.py", line 112, in __call__
    await self.middleware_stack(scope, receive, send)
  File "/data1/work/.conda/envs/nlp/lib/python3.8/site-packages/starlette/middleware/errors.py", line 181, in __call__
    raise exc
  File "/data1/work/.conda/envs/nlp/lib/python3.8/site-packages/starlette/middleware/errors.py", line 159, in __call__
    await self.app(scope, receive, _send)
  File "/data1/work/.conda/envs/nlp/lib/python3.8/site-packages/starlette/middleware/base.py", line 63, in __call__
    response = await self.dispatch_func(request, call_next)
  File "/data1/work/repos/light_chat/main.py", line 63, in db_session_middleware
    response = await call_next(request)
  File "/data1/work/.conda/envs/nlp/lib/python3.8/site-packages/starlette/middleware/base.py", line 44, in call_next
    raise app_exc
  File "/data1/work/.conda/envs/nlp/lib/python3.8/site-packages/starlette/middleware/base.py", line 34, in coro
    await self.app(scope, request.receive, send_stream.send)
  File "/data1/work/.conda/envs/nlp/lib/python3.8/site-packages/starlette/middleware/cors.py", line 92, in __call__
    await self.simple_response(scope, receive, send, request_headers=headers)
  File "/data1/work/.conda/envs/nlp/lib/python3.8/site-packages/starlette/middleware/cors.py", line 147, in simple_response
    await self.app(scope, receive, send)
  File "/data1/work/.conda/envs/nlp/lib/python3.8/site-packages/starlette/exceptions.py", line 82, in __call__
    raise exc
  File "/data1/work/.conda/envs/nlp/lib/python3.8/site-packages/starlette/exceptions.py", line 71, in __call__
    await self.app(scope, receive, sender)
  File "/data1/work/.conda/envs/nlp/lib/python3.8/site-packages/fastapi/middleware/asyncexitstack.py", line 21, in __call__
    raise e
  File "/data1/work/.conda/envs/nlp/lib/python3.8/site-packages/fastapi/middleware/asyncexitstack.py", line 18, in __call__
    await self.app(scope, receive, send)
  File "/data1/work/.conda/envs/nlp/lib/python3.8/site-packages/starlette/routing.py", line 656, in __call__
    await route.handle(scope, receive, send)
  File "/data1/work/.conda/envs/nlp/lib/python3.8/site-packages/starlette/routing.py", line 259, in handle
    await self.app(scope, receive, send)
  File "/data1/work/.conda/envs/nlp/lib/python3.8/site-packages/starlette/routing.py", line 61, in app
    response = await func(request)
  File "/data1/work/.conda/envs/nlp/lib/python3.8/site-packages/fastapi/routing.py", line 227, in app
    raw_response = await run_endpoint_function(
  File "/data1/work/.conda/envs/nlp/lib/python3.8/site-packages/fastapi/routing.py", line 162, in run_endpoint_function
    return await run_in_threadpool(dependant.call, **values)
  File "/data1/work/.conda/envs/nlp/lib/python3.8/site-packages/starlette/concurrency.py", line 39, in run_in_threadpool
    return await anyio.to_thread.run_sync(func, *args)
  File "/data1/work/.conda/envs/nlp/lib/python3.8/site-packages/anyio/to_thread.py", line 28, in run_sync
    return await get_asynclib().run_sync_in_worker_thread(func, *args, cancellable=cancellable,
  File "/data1/work/.conda/envs/nlp/lib/python3.8/site-packages/anyio/_backends/_asyncio.py", line 818, in run_sync_in_worker_thread
    return await future
  File "/data1/work/.conda/envs/nlp/lib/python3.8/site-packages/anyio/_backends/_asyncio.py", line 754, in run
    result = context.run(func, *args)
  File "/data1/work/repos/light_chat/main.py", line 184, in hist_message
    return dal.get_hist_message(db, current_user, start_id, limit)
  File "/data1/work/repos/light_chat/dal.py", line 372, in get_hist_message
    query = db.query(models.Message).filter(models.Message.topicid== topicid)
AttributeError: type object 'Message' has no attribute 'topicid'
2022-05-26 16:35:22,222, ERROR Exception in ASGI application
Traceback (most recent call last):
  File "/data1/work/.conda/envs/nlp/lib/python3.8/site-packages/uvicorn/protocols/http/httptools_impl.py", line 372, in run_asgi
    result = await app(self.scope, self.receive, self.send)
  File "/data1/work/.conda/envs/nlp/lib/python3.8/site-packages/uvicorn/middleware/proxy_headers.py", line 75, in __call__
    return await self.app(scope, receive, send)
  File "/data1/work/.conda/envs/nlp/lib/python3.8/site-packages/uvicorn/middleware/debug.py", line 96, in __call__
    raise exc from None
  File "/data1/work/.conda/envs/nlp/lib/python3.8/site-packages/uvicorn/middleware/debug.py", line 93, in __call__
    await self.app(scope, receive, inner_send)
  File "/data1/work/.conda/envs/nlp/lib/python3.8/site-packages/fastapi/applications.py", line 261, in __call__
    await super().__call__(scope, receive, send)
  File "/data1/work/.conda/envs/nlp/lib/python3.8/site-packages/starlette/applications.py", line 112, in __call__
    await self.middleware_stack(scope, receive, send)
  File "/data1/work/.conda/envs/nlp/lib/python3.8/site-packages/starlette/middleware/errors.py", line 181, in __call__
    raise exc
  File "/data1/work/.conda/envs/nlp/lib/python3.8/site-packages/starlette/middleware/errors.py", line 159, in __call__
    await self.app(scope, receive, _send)
  File "/data1/work/.conda/envs/nlp/lib/python3.8/site-packages/starlette/middleware/base.py", line 63, in __call__
    response = await self.dispatch_func(request, call_next)
  File "/data1/work/repos/light_chat/main.py", line 63, in db_session_middleware
    response = await call_next(request)
  File "/data1/work/.conda/envs/nlp/lib/python3.8/site-packages/starlette/middleware/base.py", line 44, in call_next
    raise app_exc
  File "/data1/work/.conda/envs/nlp/lib/python3.8/site-packages/starlette/middleware/base.py", line 34, in coro
    await self.app(scope, request.receive, send_stream.send)
  File "/data1/work/.conda/envs/nlp/lib/python3.8/site-packages/starlette/middleware/cors.py", line 92, in __call__
    await self.simple_response(scope, receive, send, request_headers=headers)
  File "/data1/work/.conda/envs/nlp/lib/python3.8/site-packages/starlette/middleware/cors.py", line 147, in simple_response
    await self.app(scope, receive, send)
  File "/data1/work/.conda/envs/nlp/lib/python3.8/site-packages/starlette/exceptions.py", line 82, in __call__
    raise exc
  File "/data1/work/.conda/envs/nlp/lib/python3.8/site-packages/starlette/exceptions.py", line 71, in __call__
    await self.app(scope, receive, sender)
  File "/data1/work/.conda/envs/nlp/lib/python3.8/site-packages/fastapi/middleware/asyncexitstack.py", line 21, in __call__
    raise e
  File "/data1/work/.conda/envs/nlp/lib/python3.8/site-packages/fastapi/middleware/asyncexitstack.py", line 18, in __call__
    await self.app(scope, receive, send)
  File "/data1/work/.conda/envs/nlp/lib/python3.8/site-packages/starlette/routing.py", line 656, in __call__
    await route.handle(scope, receive, send)
  File "/data1/work/.conda/envs/nlp/lib/python3.8/site-packages/starlette/routing.py", line 259, in handle
    await self.app(scope, receive, send)
  File "/data1/work/.conda/envs/nlp/lib/python3.8/site-packages/starlette/routing.py", line 61, in app
    response = await func(request)
  File "/data1/work/.conda/envs/nlp/lib/python3.8/site-packages/fastapi/routing.py", line 227, in app
    raw_response = await run_endpoint_function(
  File "/data1/work/.conda/envs/nlp/lib/python3.8/site-packages/fastapi/routing.py", line 160, in run_endpoint_function
    return await dependant.call(**values)
  File "/data1/work/repos/light_chat/main.py", line 217, in pop_message
    rst = await dal.pop_user_message(db, current_userid, start_id)
  File "/data1/work/repos/light_chat/dal.py", line 419, in pop_user_message
    msg_cnt = _get_hist_message_count(db, userid, visiable)
  File "/data1/work/repos/light_chat/dal.py", line 336, in _get_hist_message_count
    query = db.query(sqlalchemy.func.count(models.Message.id)).filter(models.Message.topicid== topicid)
AttributeError: type object 'Message' has no attribute 'topicid'
2022-05-26 16:35:38,089, ERROR Exception in ASGI application
Traceback (most recent call last):
  File "/data1/work/.conda/envs/nlp/lib/python3.8/site-packages/uvicorn/protocols/http/httptools_impl.py", line 372, in run_asgi
    result = await app(self.scope, self.receive, self.send)
  File "/data1/work/.conda/envs/nlp/lib/python3.8/site-packages/uvicorn/middleware/proxy_headers.py", line 75, in __call__
    return await self.app(scope, receive, send)
  File "/data1/work/.conda/envs/nlp/lib/python3.8/site-packages/uvicorn/middleware/debug.py", line 96, in __call__
    raise exc from None
  File "/data1/work/.conda/envs/nlp/lib/python3.8/site-packages/uvicorn/middleware/debug.py", line 93, in __call__
    await self.app(scope, receive, inner_send)
  File "/data1/work/.conda/envs/nlp/lib/python3.8/site-packages/fastapi/applications.py", line 261, in __call__
    await super().__call__(scope, receive, send)
  File "/data1/work/.conda/envs/nlp/lib/python3.8/site-packages/starlette/applications.py", line 112, in __call__
    await self.middleware_stack(scope, receive, send)
  File "/data1/work/.conda/envs/nlp/lib/python3.8/site-packages/starlette/middleware/errors.py", line 181, in __call__
    raise exc
  File "/data1/work/.conda/envs/nlp/lib/python3.8/site-packages/starlette/middleware/errors.py", line 159, in __call__
    await self.app(scope, receive, _send)
  File "/data1/work/.conda/envs/nlp/lib/python3.8/site-packages/starlette/middleware/base.py", line 63, in __call__
    response = await self.dispatch_func(request, call_next)
  File "/data1/work/repos/light_chat/main.py", line 63, in db_session_middleware
    response = await call_next(request)
  File "/data1/work/.conda/envs/nlp/lib/python3.8/site-packages/starlette/middleware/base.py", line 44, in call_next
    raise app_exc
  File "/data1/work/.conda/envs/nlp/lib/python3.8/site-packages/starlette/middleware/base.py", line 34, in coro
    await self.app(scope, request.receive, send_stream.send)
  File "/data1/work/.conda/envs/nlp/lib/python3.8/site-packages/starlette/middleware/cors.py", line 92, in __call__
    await self.simple_response(scope, receive, send, request_headers=headers)
  File "/data1/work/.conda/envs/nlp/lib/python3.8/site-packages/starlette/middleware/cors.py", line 147, in simple_response
    await self.app(scope, receive, send)
  File "/data1/work/.conda/envs/nlp/lib/python3.8/site-packages/starlette/exceptions.py", line 82, in __call__
    raise exc
  File "/data1/work/.conda/envs/nlp/lib/python3.8/site-packages/starlette/exceptions.py", line 71, in __call__
    await self.app(scope, receive, sender)
  File "/data1/work/.conda/envs/nlp/lib/python3.8/site-packages/fastapi/middleware/asyncexitstack.py", line 21, in __call__
    raise e
  File "/data1/work/.conda/envs/nlp/lib/python3.8/site-packages/fastapi/middleware/asyncexitstack.py", line 18, in __call__
    await self.app(scope, receive, send)
  File "/data1/work/.conda/envs/nlp/lib/python3.8/site-packages/starlette/routing.py", line 656, in __call__
    await route.handle(scope, receive, send)
  File "/data1/work/.conda/envs/nlp/lib/python3.8/site-packages/starlette/routing.py", line 259, in handle
    await self.app(scope, receive, send)
  File "/data1/work/.conda/envs/nlp/lib/python3.8/site-packages/starlette/routing.py", line 61, in app
    response = await func(request)
  File "/data1/work/.conda/envs/nlp/lib/python3.8/site-packages/fastapi/routing.py", line 227, in app
    raw_response = await run_endpoint_function(
  File "/data1/work/.conda/envs/nlp/lib/python3.8/site-packages/fastapi/routing.py", line 162, in run_endpoint_function
    return await run_in_threadpool(dependant.call, **values)
  File "/data1/work/.conda/envs/nlp/lib/python3.8/site-packages/starlette/concurrency.py", line 39, in run_in_threadpool
    return await anyio.to_thread.run_sync(func, *args)
  File "/data1/work/.conda/envs/nlp/lib/python3.8/site-packages/anyio/to_thread.py", line 28, in run_sync
    return await get_asynclib().run_sync_in_worker_thread(func, *args, cancellable=cancellable,
  File "/data1/work/.conda/envs/nlp/lib/python3.8/site-packages/anyio/_backends/_asyncio.py", line 818, in run_sync_in_worker_thread
    return await future
  File "/data1/work/.conda/envs/nlp/lib/python3.8/site-packages/anyio/_backends/_asyncio.py", line 754, in run
    result = context.run(func, *args)
  File "/data1/work/repos/light_chat/main.py", line 184, in hist_message
    return dal.get_hist_message(db, current_user, start_id, limit)
  File "/data1/work/repos/light_chat/dal.py", line 372, in get_hist_message
    query = db.query(models.Message).filter(models.Message.topicid== topicid)
AttributeError: type object 'Message' has no attribute 'topicid'
2022-05-26 16:35:38,180, ERROR Exception in ASGI application
Traceback (most recent call last):
  File "/data1/work/.conda/envs/nlp/lib/python3.8/site-packages/uvicorn/protocols/http/httptools_impl.py", line 372, in run_asgi
    result = await app(self.scope, self.receive, self.send)
  File "/data1/work/.conda/envs/nlp/lib/python3.8/site-packages/uvicorn/middleware/proxy_headers.py", line 75, in __call__
    return await self.app(scope, receive, send)
  File "/data1/work/.conda/envs/nlp/lib/python3.8/site-packages/uvicorn/middleware/debug.py", line 96, in __call__
    raise exc from None
  File "/data1/work/.conda/envs/nlp/lib/python3.8/site-packages/uvicorn/middleware/debug.py", line 93, in __call__
    await self.app(scope, receive, inner_send)
  File "/data1/work/.conda/envs/nlp/lib/python3.8/site-packages/fastapi/applications.py", line 261, in __call__
    await super().__call__(scope, receive, send)
  File "/data1/work/.conda/envs/nlp/lib/python3.8/site-packages/starlette/applications.py", line 112, in __call__
    await self.middleware_stack(scope, receive, send)
  File "/data1/work/.conda/envs/nlp/lib/python3.8/site-packages/starlette/middleware/errors.py", line 181, in __call__
    raise exc
  File "/data1/work/.conda/envs/nlp/lib/python3.8/site-packages/starlette/middleware/errors.py", line 159, in __call__
    await self.app(scope, receive, _send)
  File "/data1/work/.conda/envs/nlp/lib/python3.8/site-packages/starlette/middleware/base.py", line 63, in __call__
    response = await self.dispatch_func(request, call_next)
  File "/data1/work/repos/light_chat/main.py", line 63, in db_session_middleware
    response = await call_next(request)
  File "/data1/work/.conda/envs/nlp/lib/python3.8/site-packages/starlette/middleware/base.py", line 44, in call_next
    raise app_exc
  File "/data1/work/.conda/envs/nlp/lib/python3.8/site-packages/starlette/middleware/base.py", line 34, in coro
    await self.app(scope, request.receive, send_stream.send)
  File "/data1/work/.conda/envs/nlp/lib/python3.8/site-packages/starlette/middleware/cors.py", line 92, in __call__
    await self.simple_response(scope, receive, send, request_headers=headers)
  File "/data1/work/.conda/envs/nlp/lib/python3.8/site-packages/starlette/middleware/cors.py", line 147, in simple_response
    await self.app(scope, receive, send)
  File "/data1/work/.conda/envs/nlp/lib/python3.8/site-packages/starlette/exceptions.py", line 82, in __call__
    raise exc
  File "/data1/work/.conda/envs/nlp/lib/python3.8/site-packages/starlette/exceptions.py", line 71, in __call__
    await self.app(scope, receive, sender)
  File "/data1/work/.conda/envs/nlp/lib/python3.8/site-packages/fastapi/middleware/asyncexitstack.py", line 21, in __call__
    raise e
  File "/data1/work/.conda/envs/nlp/lib/python3.8/site-packages/fastapi/middleware/asyncexitstack.py", line 18, in __call__
    await self.app(scope, receive, send)
  File "/data1/work/.conda/envs/nlp/lib/python3.8/site-packages/starlette/routing.py", line 656, in __call__
    await route.handle(scope, receive, send)
  File "/data1/work/.conda/envs/nlp/lib/python3.8/site-packages/starlette/routing.py", line 259, in handle
    await self.app(scope, receive, send)
  File "/data1/work/.conda/envs/nlp/lib/python3.8/site-packages/starlette/routing.py", line 61, in app
    response = await func(request)
  File "/data1/work/.conda/envs/nlp/lib/python3.8/site-packages/fastapi/routing.py", line 227, in app
    raw_response = await run_endpoint_function(
  File "/data1/work/.conda/envs/nlp/lib/python3.8/site-packages/fastapi/routing.py", line 160, in run_endpoint_function
    return await dependant.call(**values)
  File "/data1/work/repos/light_chat/main.py", line 217, in pop_message
    rst = await dal.pop_user_message(db, current_userid, start_id)
  File "/data1/work/repos/light_chat/dal.py", line 419, in pop_user_message
    msg_cnt = _get_hist_message_count(db, userid, visiable)
  File "/data1/work/repos/light_chat/dal.py", line 336, in _get_hist_message_count
    query = db.query(sqlalchemy.func.count(models.Message.id)).filter(models.Message.topicid== topicid)
AttributeError: type object 'Message' has no attribute 'topicid'
2022-05-26 16:59:30,068, DEBUG Starting new HTTP connection (1): 127.0.0.1:8080
2022-05-26 16:59:33,574, DEBUG http://127.0.0.1:8080 "POST /api/v0/generate HTTP/1.1" 200 155
2022-05-26 16:59:40,631, DEBUG Starting new HTTP connection (1): 127.0.0.1:8080
2022-05-26 16:59:44,025, DEBUG http://127.0.0.1:8080 "POST /api/v0/generate HTTP/1.1" 200 332
2022-05-26 17:10:53,701, INFO Shutting down
2022-05-26 17:10:53,802, INFO Waiting for application shutdown.
2022-05-26 17:10:53,803, INFO Application shutdown complete.
2022-05-26 17:10:53,803, INFO Finished server process [4035045]
