2022-05-06 01:41:22,550, WARNING Invalid HTTP request received.
Traceback (most recent call last):
  File "/data1/work/.conda/envs/nlp/lib/python3.8/site-packages/uvicorn/protocols/http/h11_impl.py", line 129, in handle_events
    event = self.conn.next_event()
  File "/data1/work/.conda/envs/nlp/lib/python3.8/site-packages/h11/_connection.py", line 443, in next_event
    exc._reraise_as_remote_protocol_error()
  File "/data1/work/.conda/envs/nlp/lib/python3.8/site-packages/h11/_util.py", line 76, in _reraise_as_remote_protocol_error
    raise self
  File "/data1/work/.conda/envs/nlp/lib/python3.8/site-packages/h11/_connection.py", line 425, in next_event
    event = self._extract_next_receive_event()
  File "/data1/work/.conda/envs/nlp/lib/python3.8/site-packages/h11/_connection.py", line 367, in _extract_next_receive_event
    event = self._reader(self._receive_buffer)
  File "/data1/work/.conda/envs/nlp/lib/python3.8/site-packages/h11/_readers.py", line 68, in maybe_read_from_IDLE_client
    raise LocalProtocolError("illegal request line")
h11._util.RemoteProtocolError: illegal request line
2022-05-06 01:41:30,659, WARNING Invalid HTTP request received.
Traceback (most recent call last):
  File "/data1/work/.conda/envs/nlp/lib/python3.8/site-packages/uvicorn/protocols/http/h11_impl.py", line 129, in handle_events
    event = self.conn.next_event()
  File "/data1/work/.conda/envs/nlp/lib/python3.8/site-packages/h11/_connection.py", line 443, in next_event
    exc._reraise_as_remote_protocol_error()
  File "/data1/work/.conda/envs/nlp/lib/python3.8/site-packages/h11/_util.py", line 76, in _reraise_as_remote_protocol_error
    raise self
  File "/data1/work/.conda/envs/nlp/lib/python3.8/site-packages/h11/_connection.py", line 425, in next_event
    event = self._extract_next_receive_event()
  File "/data1/work/.conda/envs/nlp/lib/python3.8/site-packages/h11/_connection.py", line 367, in _extract_next_receive_event
    event = self._reader(self._receive_buffer)
  File "/data1/work/.conda/envs/nlp/lib/python3.8/site-packages/h11/_readers.py", line 68, in maybe_read_from_IDLE_client
    raise LocalProtocolError("illegal request line")
h11._util.RemoteProtocolError: illegal request line
2022-05-06 01:41:34,130, WARNING Invalid HTTP request received.
Traceback (most recent call last):
  File "/data1/work/.conda/envs/nlp/lib/python3.8/site-packages/uvicorn/protocols/http/h11_impl.py", line 129, in handle_events
    event = self.conn.next_event()
  File "/data1/work/.conda/envs/nlp/lib/python3.8/site-packages/h11/_connection.py", line 443, in next_event
    exc._reraise_as_remote_protocol_error()
  File "/data1/work/.conda/envs/nlp/lib/python3.8/site-packages/h11/_util.py", line 76, in _reraise_as_remote_protocol_error
    raise self
  File "/data1/work/.conda/envs/nlp/lib/python3.8/site-packages/h11/_connection.py", line 425, in next_event
    event = self._extract_next_receive_event()
  File "/data1/work/.conda/envs/nlp/lib/python3.8/site-packages/h11/_connection.py", line 367, in _extract_next_receive_event
    event = self._reader(self._receive_buffer)
  File "/data1/work/.conda/envs/nlp/lib/python3.8/site-packages/h11/_readers.py", line 72, in maybe_read_from_IDLE_client
    matches = validate(
  File "/data1/work/.conda/envs/nlp/lib/python3.8/site-packages/h11/_util.py", line 88, in validate
    raise LocalProtocolError(msg)
h11._util.RemoteProtocolError: illegal request line: bytearray(b'SM')
2022-05-06 02:20:49,768, WARNING Invalid HTTP request received.
Traceback (most recent call last):
  File "/data1/work/.conda/envs/nlp/lib/python3.8/site-packages/uvicorn/protocols/http/h11_impl.py", line 129, in handle_events
    event = self.conn.next_event()
  File "/data1/work/.conda/envs/nlp/lib/python3.8/site-packages/h11/_connection.py", line 443, in next_event
    exc._reraise_as_remote_protocol_error()
  File "/data1/work/.conda/envs/nlp/lib/python3.8/site-packages/h11/_util.py", line 76, in _reraise_as_remote_protocol_error
    raise self
  File "/data1/work/.conda/envs/nlp/lib/python3.8/site-packages/h11/_connection.py", line 425, in next_event
    event = self._extract_next_receive_event()
  File "/data1/work/.conda/envs/nlp/lib/python3.8/site-packages/h11/_connection.py", line 367, in _extract_next_receive_event
    event = self._reader(self._receive_buffer)
  File "/data1/work/.conda/envs/nlp/lib/python3.8/site-packages/h11/_readers.py", line 68, in maybe_read_from_IDLE_client
    raise LocalProtocolError("illegal request line")
h11._util.RemoteProtocolError: illegal request line
2022-05-06 02:20:52,819, WARNING Invalid HTTP request received.
Traceback (most recent call last):
  File "/data1/work/.conda/envs/nlp/lib/python3.8/site-packages/uvicorn/protocols/http/h11_impl.py", line 129, in handle_events
    event = self.conn.next_event()
  File "/data1/work/.conda/envs/nlp/lib/python3.8/site-packages/h11/_connection.py", line 443, in next_event
    exc._reraise_as_remote_protocol_error()
  File "/data1/work/.conda/envs/nlp/lib/python3.8/site-packages/h11/_util.py", line 76, in _reraise_as_remote_protocol_error
    raise self
  File "/data1/work/.conda/envs/nlp/lib/python3.8/site-packages/h11/_connection.py", line 425, in next_event
    event = self._extract_next_receive_event()
  File "/data1/work/.conda/envs/nlp/lib/python3.8/site-packages/h11/_connection.py", line 367, in _extract_next_receive_event
    event = self._reader(self._receive_buffer)
  File "/data1/work/.conda/envs/nlp/lib/python3.8/site-packages/h11/_readers.py", line 68, in maybe_read_from_IDLE_client
    raise LocalProtocolError("illegal request line")
h11._util.RemoteProtocolError: illegal request line
2022-05-06 02:21:04,994, WARNING Invalid HTTP request received.
Traceback (most recent call last):
  File "/data1/work/.conda/envs/nlp/lib/python3.8/site-packages/uvicorn/protocols/http/h11_impl.py", line 129, in handle_events
    event = self.conn.next_event()
  File "/data1/work/.conda/envs/nlp/lib/python3.8/site-packages/h11/_connection.py", line 443, in next_event
    exc._reraise_as_remote_protocol_error()
  File "/data1/work/.conda/envs/nlp/lib/python3.8/site-packages/h11/_util.py", line 76, in _reraise_as_remote_protocol_error
    raise self
  File "/data1/work/.conda/envs/nlp/lib/python3.8/site-packages/h11/_connection.py", line 425, in next_event
    event = self._extract_next_receive_event()
  File "/data1/work/.conda/envs/nlp/lib/python3.8/site-packages/h11/_connection.py", line 367, in _extract_next_receive_event
    event = self._reader(self._receive_buffer)
  File "/data1/work/.conda/envs/nlp/lib/python3.8/site-packages/h11/_readers.py", line 68, in maybe_read_from_IDLE_client
    raise LocalProtocolError("illegal request line")
h11._util.RemoteProtocolError: illegal request line
2022-05-06 02:57:16,327, WARNING Invalid HTTP request received.
Traceback (most recent call last):
  File "/data1/work/.conda/envs/nlp/lib/python3.8/site-packages/uvicorn/protocols/http/h11_impl.py", line 129, in handle_events
    event = self.conn.next_event()
  File "/data1/work/.conda/envs/nlp/lib/python3.8/site-packages/h11/_connection.py", line 443, in next_event
    exc._reraise_as_remote_protocol_error()
  File "/data1/work/.conda/envs/nlp/lib/python3.8/site-packages/h11/_util.py", line 76, in _reraise_as_remote_protocol_error
    raise self
  File "/data1/work/.conda/envs/nlp/lib/python3.8/site-packages/h11/_connection.py", line 425, in next_event
    event = self._extract_next_receive_event()
  File "/data1/work/.conda/envs/nlp/lib/python3.8/site-packages/h11/_connection.py", line 367, in _extract_next_receive_event
    event = self._reader(self._receive_buffer)
  File "/data1/work/.conda/envs/nlp/lib/python3.8/site-packages/h11/_readers.py", line 68, in maybe_read_from_IDLE_client
    raise LocalProtocolError("illegal request line")
h11._util.RemoteProtocolError: illegal request line
2022-05-06 08:10:38,802, WARNING Invalid HTTP request received.
Traceback (most recent call last):
  File "/data1/work/.conda/envs/nlp/lib/python3.8/site-packages/uvicorn/protocols/http/h11_impl.py", line 129, in handle_events
    event = self.conn.next_event()
  File "/data1/work/.conda/envs/nlp/lib/python3.8/site-packages/h11/_connection.py", line 443, in next_event
    exc._reraise_as_remote_protocol_error()
  File "/data1/work/.conda/envs/nlp/lib/python3.8/site-packages/h11/_util.py", line 76, in _reraise_as_remote_protocol_error
    raise self
  File "/data1/work/.conda/envs/nlp/lib/python3.8/site-packages/h11/_connection.py", line 425, in next_event
    event = self._extract_next_receive_event()
  File "/data1/work/.conda/envs/nlp/lib/python3.8/site-packages/h11/_connection.py", line 367, in _extract_next_receive_event
    event = self._reader(self._receive_buffer)
  File "/data1/work/.conda/envs/nlp/lib/python3.8/site-packages/h11/_readers.py", line 68, in maybe_read_from_IDLE_client
    raise LocalProtocolError("illegal request line")
h11._util.RemoteProtocolError: illegal request line
2022-05-06 08:10:45,442, WARNING Invalid HTTP request received.
Traceback (most recent call last):
  File "/data1/work/.conda/envs/nlp/lib/python3.8/site-packages/uvicorn/protocols/http/h11_impl.py", line 129, in handle_events
    event = self.conn.next_event()
  File "/data1/work/.conda/envs/nlp/lib/python3.8/site-packages/h11/_connection.py", line 443, in next_event
    exc._reraise_as_remote_protocol_error()
  File "/data1/work/.conda/envs/nlp/lib/python3.8/site-packages/h11/_util.py", line 76, in _reraise_as_remote_protocol_error
    raise self
  File "/data1/work/.conda/envs/nlp/lib/python3.8/site-packages/h11/_connection.py", line 425, in next_event
    event = self._extract_next_receive_event()
  File "/data1/work/.conda/envs/nlp/lib/python3.8/site-packages/h11/_connection.py", line 367, in _extract_next_receive_event
    event = self._reader(self._receive_buffer)
  File "/data1/work/.conda/envs/nlp/lib/python3.8/site-packages/h11/_readers.py", line 68, in maybe_read_from_IDLE_client
    raise LocalProtocolError("illegal request line")
h11._util.RemoteProtocolError: illegal request line
2022-05-06 08:10:48,226, WARNING Invalid HTTP request received.
Traceback (most recent call last):
  File "/data1/work/.conda/envs/nlp/lib/python3.8/site-packages/uvicorn/protocols/http/h11_impl.py", line 129, in handle_events
    event = self.conn.next_event()
  File "/data1/work/.conda/envs/nlp/lib/python3.8/site-packages/h11/_connection.py", line 443, in next_event
    exc._reraise_as_remote_protocol_error()
  File "/data1/work/.conda/envs/nlp/lib/python3.8/site-packages/h11/_util.py", line 76, in _reraise_as_remote_protocol_error
    raise self
  File "/data1/work/.conda/envs/nlp/lib/python3.8/site-packages/h11/_connection.py", line 425, in next_event
    event = self._extract_next_receive_event()
  File "/data1/work/.conda/envs/nlp/lib/python3.8/site-packages/h11/_connection.py", line 367, in _extract_next_receive_event
    event = self._reader(self._receive_buffer)
  File "/data1/work/.conda/envs/nlp/lib/python3.8/site-packages/h11/_readers.py", line 72, in maybe_read_from_IDLE_client
    matches = validate(
  File "/data1/work/.conda/envs/nlp/lib/python3.8/site-packages/h11/_util.py", line 88, in validate
    raise LocalProtocolError(msg)
h11._util.RemoteProtocolError: illegal request line: bytearray(b'SM')
2022-05-06 13:39:01,175, INFO Shutting down
2022-05-06 13:39:01,277, INFO Waiting for application shutdown.
2022-05-06 13:39:01,278, INFO Application shutdown complete.
2022-05-06 13:39:01,278, INFO Finished server process [1832552]
