2022-05-18 01:41:58,468, WARNING Invalid HTTP request received.
Traceback (most recent call last):
  File "/data1/work/.conda/envs/nlp/lib/python3.8/site-packages/uvicorn/protocols/http/h11_impl.py", line 129, in handle_events
    event = self.conn.next_event()
  File "/data1/work/.conda/envs/nlp/lib/python3.8/site-packages/h11/_connection.py", line 443, in next_event
    exc._reraise_as_remote_protocol_error()
  File "/data1/work/.conda/envs/nlp/lib/python3.8/site-packages/h11/_util.py", line 76, in _reraise_as_remote_protocol_error
    raise self
  File "/data1/work/.conda/envs/nlp/lib/python3.8/site-packages/h11/_connection.py", line 425, in next_event
    event = self._extract_next_receive_event()
  File "/data1/work/.conda/envs/nlp/lib/python3.8/site-packages/h11/_connection.py", line 367, in _extract_next_receive_event
    event = self._reader(self._receive_buffer)
  File "/data1/work/.conda/envs/nlp/lib/python3.8/site-packages/h11/_readers.py", line 68, in maybe_read_from_IDLE_client
    raise LocalProtocolError("illegal request line")
h11._util.RemoteProtocolError: illegal request line
2022-05-18 02:35:16,533, WARNING Invalid HTTP request received.
Traceback (most recent call last):
  File "/data1/work/.conda/envs/nlp/lib/python3.8/site-packages/uvicorn/protocols/http/h11_impl.py", line 129, in handle_events
    event = self.conn.next_event()
  File "/data1/work/.conda/envs/nlp/lib/python3.8/site-packages/h11/_connection.py", line 443, in next_event
    exc._reraise_as_remote_protocol_error()
  File "/data1/work/.conda/envs/nlp/lib/python3.8/site-packages/h11/_util.py", line 76, in _reraise_as_remote_protocol_error
    raise self
  File "/data1/work/.conda/envs/nlp/lib/python3.8/site-packages/h11/_connection.py", line 425, in next_event
    event = self._extract_next_receive_event()
  File "/data1/work/.conda/envs/nlp/lib/python3.8/site-packages/h11/_connection.py", line 367, in _extract_next_receive_event
    event = self._reader(self._receive_buffer)
  File "/data1/work/.conda/envs/nlp/lib/python3.8/site-packages/h11/_readers.py", line 68, in maybe_read_from_IDLE_client
    raise LocalProtocolError("illegal request line")
h11._util.RemoteProtocolError: illegal request line
2022-05-18 05:25:20,471, WARNING Invalid HTTP request received.
Traceback (most recent call last):
  File "/data1/work/.conda/envs/nlp/lib/python3.8/site-packages/uvicorn/protocols/http/h11_impl.py", line 129, in handle_events
    event = self.conn.next_event()
  File "/data1/work/.conda/envs/nlp/lib/python3.8/site-packages/h11/_connection.py", line 443, in next_event
    exc._reraise_as_remote_protocol_error()
  File "/data1/work/.conda/envs/nlp/lib/python3.8/site-packages/h11/_util.py", line 76, in _reraise_as_remote_protocol_error
    raise self
  File "/data1/work/.conda/envs/nlp/lib/python3.8/site-packages/h11/_connection.py", line 425, in next_event
    event = self._extract_next_receive_event()
  File "/data1/work/.conda/envs/nlp/lib/python3.8/site-packages/h11/_connection.py", line 367, in _extract_next_receive_event
    event = self._reader(self._receive_buffer)
  File "/data1/work/.conda/envs/nlp/lib/python3.8/site-packages/h11/_readers.py", line 68, in maybe_read_from_IDLE_client
    raise LocalProtocolError("illegal request line")
h11._util.RemoteProtocolError: illegal request line
2022-05-18 05:25:25,459, WARNING Invalid HTTP request received.
Traceback (most recent call last):
  File "/data1/work/.conda/envs/nlp/lib/python3.8/site-packages/uvicorn/protocols/http/h11_impl.py", line 129, in handle_events
    event = self.conn.next_event()
  File "/data1/work/.conda/envs/nlp/lib/python3.8/site-packages/h11/_connection.py", line 443, in next_event
    exc._reraise_as_remote_protocol_error()
  File "/data1/work/.conda/envs/nlp/lib/python3.8/site-packages/h11/_util.py", line 76, in _reraise_as_remote_protocol_error
    raise self
  File "/data1/work/.conda/envs/nlp/lib/python3.8/site-packages/h11/_connection.py", line 425, in next_event
    event = self._extract_next_receive_event()
  File "/data1/work/.conda/envs/nlp/lib/python3.8/site-packages/h11/_connection.py", line 367, in _extract_next_receive_event
    event = self._reader(self._receive_buffer)
  File "/data1/work/.conda/envs/nlp/lib/python3.8/site-packages/h11/_readers.py", line 68, in maybe_read_from_IDLE_client
    raise LocalProtocolError("illegal request line")
h11._util.RemoteProtocolError: illegal request line
2022-05-18 05:25:27,961, WARNING Invalid HTTP request received.
Traceback (most recent call last):
  File "/data1/work/.conda/envs/nlp/lib/python3.8/site-packages/uvicorn/protocols/http/h11_impl.py", line 129, in handle_events
    event = self.conn.next_event()
  File "/data1/work/.conda/envs/nlp/lib/python3.8/site-packages/h11/_connection.py", line 443, in next_event
    exc._reraise_as_remote_protocol_error()
  File "/data1/work/.conda/envs/nlp/lib/python3.8/site-packages/h11/_util.py", line 76, in _reraise_as_remote_protocol_error
    raise self
  File "/data1/work/.conda/envs/nlp/lib/python3.8/site-packages/h11/_connection.py", line 425, in next_event
    event = self._extract_next_receive_event()
  File "/data1/work/.conda/envs/nlp/lib/python3.8/site-packages/h11/_connection.py", line 367, in _extract_next_receive_event
    event = self._reader(self._receive_buffer)
  File "/data1/work/.conda/envs/nlp/lib/python3.8/site-packages/h11/_readers.py", line 72, in maybe_read_from_IDLE_client
    matches = validate(
  File "/data1/work/.conda/envs/nlp/lib/python3.8/site-packages/h11/_util.py", line 88, in validate
    raise LocalProtocolError(msg)
h11._util.RemoteProtocolError: illegal request line: bytearray(b'SM')
2022-05-18 07:03:22,983, WARNING Invalid HTTP request received.
Traceback (most recent call last):
  File "/data1/work/.conda/envs/nlp/lib/python3.8/site-packages/uvicorn/protocols/http/h11_impl.py", line 129, in handle_events
    event = self.conn.next_event()
  File "/data1/work/.conda/envs/nlp/lib/python3.8/site-packages/h11/_connection.py", line 443, in next_event
    exc._reraise_as_remote_protocol_error()
  File "/data1/work/.conda/envs/nlp/lib/python3.8/site-packages/h11/_util.py", line 76, in _reraise_as_remote_protocol_error
    raise self
  File "/data1/work/.conda/envs/nlp/lib/python3.8/site-packages/h11/_connection.py", line 425, in next_event
    event = self._extract_next_receive_event()
  File "/data1/work/.conda/envs/nlp/lib/python3.8/site-packages/h11/_connection.py", line 367, in _extract_next_receive_event
    event = self._reader(self._receive_buffer)
  File "/data1/work/.conda/envs/nlp/lib/python3.8/site-packages/h11/_readers.py", line 68, in maybe_read_from_IDLE_client
    raise LocalProtocolError("illegal request line")
h11._util.RemoteProtocolError: illegal request line
2022-05-18 07:03:28,113, WARNING Invalid HTTP request received.
Traceback (most recent call last):
  File "/data1/work/.conda/envs/nlp/lib/python3.8/site-packages/uvicorn/protocols/http/h11_impl.py", line 129, in handle_events
    event = self.conn.next_event()
  File "/data1/work/.conda/envs/nlp/lib/python3.8/site-packages/h11/_connection.py", line 443, in next_event
    exc._reraise_as_remote_protocol_error()
  File "/data1/work/.conda/envs/nlp/lib/python3.8/site-packages/h11/_util.py", line 76, in _reraise_as_remote_protocol_error
    raise self
  File "/data1/work/.conda/envs/nlp/lib/python3.8/site-packages/h11/_connection.py", line 425, in next_event
    event = self._extract_next_receive_event()
  File "/data1/work/.conda/envs/nlp/lib/python3.8/site-packages/h11/_connection.py", line 367, in _extract_next_receive_event
    event = self._reader(self._receive_buffer)
  File "/data1/work/.conda/envs/nlp/lib/python3.8/site-packages/h11/_readers.py", line 68, in maybe_read_from_IDLE_client
    raise LocalProtocolError("illegal request line")
h11._util.RemoteProtocolError: illegal request line
2022-05-18 07:03:30,734, WARNING Invalid HTTP request received.
Traceback (most recent call last):
  File "/data1/work/.conda/envs/nlp/lib/python3.8/site-packages/uvicorn/protocols/http/h11_impl.py", line 129, in handle_events
    event = self.conn.next_event()
  File "/data1/work/.conda/envs/nlp/lib/python3.8/site-packages/h11/_connection.py", line 443, in next_event
    exc._reraise_as_remote_protocol_error()
  File "/data1/work/.conda/envs/nlp/lib/python3.8/site-packages/h11/_util.py", line 76, in _reraise_as_remote_protocol_error
    raise self
  File "/data1/work/.conda/envs/nlp/lib/python3.8/site-packages/h11/_connection.py", line 425, in next_event
    event = self._extract_next_receive_event()
  File "/data1/work/.conda/envs/nlp/lib/python3.8/site-packages/h11/_connection.py", line 367, in _extract_next_receive_event
    event = self._reader(self._receive_buffer)
  File "/data1/work/.conda/envs/nlp/lib/python3.8/site-packages/h11/_readers.py", line 72, in maybe_read_from_IDLE_client
    matches = validate(
  File "/data1/work/.conda/envs/nlp/lib/python3.8/site-packages/h11/_util.py", line 88, in validate
    raise LocalProtocolError(msg)
h11._util.RemoteProtocolError: illegal request line: bytearray(b'SM')
2022-05-18 13:50:38,369, WARNING Invalid HTTP request received.
Traceback (most recent call last):
  File "/data1/work/.conda/envs/nlp/lib/python3.8/site-packages/uvicorn/protocols/http/h11_impl.py", line 129, in handle_events
    event = self.conn.next_event()
  File "/data1/work/.conda/envs/nlp/lib/python3.8/site-packages/h11/_connection.py", line 443, in next_event
    exc._reraise_as_remote_protocol_error()
  File "/data1/work/.conda/envs/nlp/lib/python3.8/site-packages/h11/_util.py", line 76, in _reraise_as_remote_protocol_error
    raise self
  File "/data1/work/.conda/envs/nlp/lib/python3.8/site-packages/h11/_connection.py", line 425, in next_event
    event = self._extract_next_receive_event()
  File "/data1/work/.conda/envs/nlp/lib/python3.8/site-packages/h11/_connection.py", line 367, in _extract_next_receive_event
    event = self._reader(self._receive_buffer)
  File "/data1/work/.conda/envs/nlp/lib/python3.8/site-packages/h11/_readers.py", line 68, in maybe_read_from_IDLE_client
    raise LocalProtocolError("illegal request line")
h11._util.RemoteProtocolError: illegal request line
2022-05-18 15:43:59,875, WARNING Invalid HTTP request received.
Traceback (most recent call last):
  File "/data1/work/.conda/envs/nlp/lib/python3.8/site-packages/uvicorn/protocols/http/h11_impl.py", line 129, in handle_events
    event = self.conn.next_event()
  File "/data1/work/.conda/envs/nlp/lib/python3.8/site-packages/h11/_connection.py", line 443, in next_event
    exc._reraise_as_remote_protocol_error()
  File "/data1/work/.conda/envs/nlp/lib/python3.8/site-packages/h11/_util.py", line 76, in _reraise_as_remote_protocol_error
    raise self
  File "/data1/work/.conda/envs/nlp/lib/python3.8/site-packages/h11/_connection.py", line 425, in next_event
    event = self._extract_next_receive_event()
  File "/data1/work/.conda/envs/nlp/lib/python3.8/site-packages/h11/_connection.py", line 367, in _extract_next_receive_event
    event = self._reader(self._receive_buffer)
  File "/data1/work/.conda/envs/nlp/lib/python3.8/site-packages/h11/_readers.py", line 68, in maybe_read_from_IDLE_client
    raise LocalProtocolError("illegal request line")
h11._util.RemoteProtocolError: illegal request line
2022-05-18 15:58:02,881, WARNING Invalid HTTP request received.
Traceback (most recent call last):
  File "/data1/work/.conda/envs/nlp/lib/python3.8/site-packages/uvicorn/protocols/http/h11_impl.py", line 129, in handle_events
    event = self.conn.next_event()
  File "/data1/work/.conda/envs/nlp/lib/python3.8/site-packages/h11/_connection.py", line 443, in next_event
    exc._reraise_as_remote_protocol_error()
  File "/data1/work/.conda/envs/nlp/lib/python3.8/site-packages/h11/_util.py", line 76, in _reraise_as_remote_protocol_error
    raise self
  File "/data1/work/.conda/envs/nlp/lib/python3.8/site-packages/h11/_connection.py", line 425, in next_event
    event = self._extract_next_receive_event()
  File "/data1/work/.conda/envs/nlp/lib/python3.8/site-packages/h11/_connection.py", line 367, in _extract_next_receive_event
    event = self._reader(self._receive_buffer)
  File "/data1/work/.conda/envs/nlp/lib/python3.8/site-packages/h11/_readers.py", line 68, in maybe_read_from_IDLE_client
    raise LocalProtocolError("illegal request line")
h11._util.RemoteProtocolError: illegal request line
2022-05-18 15:58:09,171, WARNING Invalid HTTP request received.
Traceback (most recent call last):
  File "/data1/work/.conda/envs/nlp/lib/python3.8/site-packages/uvicorn/protocols/http/h11_impl.py", line 129, in handle_events
    event = self.conn.next_event()
  File "/data1/work/.conda/envs/nlp/lib/python3.8/site-packages/h11/_connection.py", line 443, in next_event
    exc._reraise_as_remote_protocol_error()
  File "/data1/work/.conda/envs/nlp/lib/python3.8/site-packages/h11/_util.py", line 76, in _reraise_as_remote_protocol_error
    raise self
  File "/data1/work/.conda/envs/nlp/lib/python3.8/site-packages/h11/_connection.py", line 425, in next_event
    event = self._extract_next_receive_event()
  File "/data1/work/.conda/envs/nlp/lib/python3.8/site-packages/h11/_connection.py", line 367, in _extract_next_receive_event
    event = self._reader(self._receive_buffer)
  File "/data1/work/.conda/envs/nlp/lib/python3.8/site-packages/h11/_readers.py", line 68, in maybe_read_from_IDLE_client
    raise LocalProtocolError("illegal request line")
h11._util.RemoteProtocolError: illegal request line
2022-05-18 18:21:46,486, WARNING Invalid HTTP request received.
Traceback (most recent call last):
  File "/data1/work/.conda/envs/nlp/lib/python3.8/site-packages/uvicorn/protocols/http/h11_impl.py", line 129, in handle_events
    event = self.conn.next_event()
  File "/data1/work/.conda/envs/nlp/lib/python3.8/site-packages/h11/_connection.py", line 443, in next_event
    exc._reraise_as_remote_protocol_error()
  File "/data1/work/.conda/envs/nlp/lib/python3.8/site-packages/h11/_util.py", line 76, in _reraise_as_remote_protocol_error
    raise self
  File "/data1/work/.conda/envs/nlp/lib/python3.8/site-packages/h11/_connection.py", line 425, in next_event
    event = self._extract_next_receive_event()
  File "/data1/work/.conda/envs/nlp/lib/python3.8/site-packages/h11/_connection.py", line 367, in _extract_next_receive_event
    event = self._reader(self._receive_buffer)
  File "/data1/work/.conda/envs/nlp/lib/python3.8/site-packages/h11/_readers.py", line 68, in maybe_read_from_IDLE_client
    raise LocalProtocolError("illegal request line")
h11._util.RemoteProtocolError: illegal request line
2022-05-18 18:21:48,209, WARNING Invalid HTTP request received.
Traceback (most recent call last):
  File "/data1/work/.conda/envs/nlp/lib/python3.8/site-packages/uvicorn/protocols/http/h11_impl.py", line 129, in handle_events
    event = self.conn.next_event()
  File "/data1/work/.conda/envs/nlp/lib/python3.8/site-packages/h11/_connection.py", line 443, in next_event
    exc._reraise_as_remote_protocol_error()
  File "/data1/work/.conda/envs/nlp/lib/python3.8/site-packages/h11/_util.py", line 76, in _reraise_as_remote_protocol_error
    raise self
  File "/data1/work/.conda/envs/nlp/lib/python3.8/site-packages/h11/_connection.py", line 425, in next_event
    event = self._extract_next_receive_event()
  File "/data1/work/.conda/envs/nlp/lib/python3.8/site-packages/h11/_connection.py", line 367, in _extract_next_receive_event
    event = self._reader(self._receive_buffer)
  File "/data1/work/.conda/envs/nlp/lib/python3.8/site-packages/h11/_readers.py", line 68, in maybe_read_from_IDLE_client
    raise LocalProtocolError("illegal request line")
h11._util.RemoteProtocolError: illegal request line
2022-05-18 18:21:55,307, WARNING Invalid HTTP request received.
Traceback (most recent call last):
  File "/data1/work/.conda/envs/nlp/lib/python3.8/site-packages/uvicorn/protocols/http/h11_impl.py", line 129, in handle_events
    event = self.conn.next_event()
  File "/data1/work/.conda/envs/nlp/lib/python3.8/site-packages/h11/_connection.py", line 443, in next_event
    exc._reraise_as_remote_protocol_error()
  File "/data1/work/.conda/envs/nlp/lib/python3.8/site-packages/h11/_util.py", line 76, in _reraise_as_remote_protocol_error
    raise self
  File "/data1/work/.conda/envs/nlp/lib/python3.8/site-packages/h11/_connection.py", line 425, in next_event
    event = self._extract_next_receive_event()
  File "/data1/work/.conda/envs/nlp/lib/python3.8/site-packages/h11/_connection.py", line 367, in _extract_next_receive_event
    event = self._reader(self._receive_buffer)
  File "/data1/work/.conda/envs/nlp/lib/python3.8/site-packages/h11/_readers.py", line 68, in maybe_read_from_IDLE_client
    raise LocalProtocolError("illegal request line")
h11._util.RemoteProtocolError: illegal request line
2022-05-18 18:21:55,961, WARNING Invalid HTTP request received.
Traceback (most recent call last):
  File "/data1/work/.conda/envs/nlp/lib/python3.8/site-packages/uvicorn/protocols/http/h11_impl.py", line 129, in handle_events
    event = self.conn.next_event()
  File "/data1/work/.conda/envs/nlp/lib/python3.8/site-packages/h11/_connection.py", line 443, in next_event
    exc._reraise_as_remote_protocol_error()
  File "/data1/work/.conda/envs/nlp/lib/python3.8/site-packages/h11/_util.py", line 76, in _reraise_as_remote_protocol_error
    raise self
  File "/data1/work/.conda/envs/nlp/lib/python3.8/site-packages/h11/_connection.py", line 425, in next_event
    event = self._extract_next_receive_event()
  File "/data1/work/.conda/envs/nlp/lib/python3.8/site-packages/h11/_connection.py", line 367, in _extract_next_receive_event
    event = self._reader(self._receive_buffer)
  File "/data1/work/.conda/envs/nlp/lib/python3.8/site-packages/h11/_readers.py", line 68, in maybe_read_from_IDLE_client
    raise LocalProtocolError("illegal request line")
h11._util.RemoteProtocolError: illegal request line
2022-05-18 18:21:58,362, WARNING Invalid HTTP request received.
Traceback (most recent call last):
  File "/data1/work/.conda/envs/nlp/lib/python3.8/site-packages/uvicorn/protocols/http/h11_impl.py", line 129, in handle_events
    event = self.conn.next_event()
  File "/data1/work/.conda/envs/nlp/lib/python3.8/site-packages/h11/_connection.py", line 443, in next_event
    exc._reraise_as_remote_protocol_error()
  File "/data1/work/.conda/envs/nlp/lib/python3.8/site-packages/h11/_util.py", line 76, in _reraise_as_remote_protocol_error
    raise self
  File "/data1/work/.conda/envs/nlp/lib/python3.8/site-packages/h11/_connection.py", line 425, in next_event
    event = self._extract_next_receive_event()
  File "/data1/work/.conda/envs/nlp/lib/python3.8/site-packages/h11/_connection.py", line 367, in _extract_next_receive_event
    event = self._reader(self._receive_buffer)
  File "/data1/work/.conda/envs/nlp/lib/python3.8/site-packages/h11/_readers.py", line 71, in maybe_read_from_IDLE_client
    raise LocalProtocolError("no request line received")
h11._util.RemoteProtocolError: no request line received
2022-05-18 18:21:59,478, WARNING Invalid HTTP request received.
Traceback (most recent call last):
  File "/data1/work/.conda/envs/nlp/lib/python3.8/site-packages/uvicorn/protocols/http/h11_impl.py", line 129, in handle_events
    event = self.conn.next_event()
  File "/data1/work/.conda/envs/nlp/lib/python3.8/site-packages/h11/_connection.py", line 443, in next_event
    exc._reraise_as_remote_protocol_error()
  File "/data1/work/.conda/envs/nlp/lib/python3.8/site-packages/h11/_util.py", line 76, in _reraise_as_remote_protocol_error
    raise self
  File "/data1/work/.conda/envs/nlp/lib/python3.8/site-packages/h11/_connection.py", line 425, in next_event
    event = self._extract_next_receive_event()
  File "/data1/work/.conda/envs/nlp/lib/python3.8/site-packages/h11/_connection.py", line 367, in _extract_next_receive_event
    event = self._reader(self._receive_buffer)
  File "/data1/work/.conda/envs/nlp/lib/python3.8/site-packages/h11/_readers.py", line 72, in maybe_read_from_IDLE_client
    matches = validate(
  File "/data1/work/.conda/envs/nlp/lib/python3.8/site-packages/h11/_util.py", line 88, in validate
    raise LocalProtocolError(msg)
h11._util.RemoteProtocolError: illegal request line: bytearray(b'OPTIONS / RTSP/1.0')
2022-05-18 18:22:06,391, WARNING Invalid HTTP request received.
Traceback (most recent call last):
  File "/data1/work/.conda/envs/nlp/lib/python3.8/site-packages/uvicorn/protocols/http/h11_impl.py", line 129, in handle_events
    event = self.conn.next_event()
  File "/data1/work/.conda/envs/nlp/lib/python3.8/site-packages/h11/_connection.py", line 443, in next_event
    exc._reraise_as_remote_protocol_error()
  File "/data1/work/.conda/envs/nlp/lib/python3.8/site-packages/h11/_util.py", line 76, in _reraise_as_remote_protocol_error
    raise self
  File "/data1/work/.conda/envs/nlp/lib/python3.8/site-packages/h11/_connection.py", line 425, in next_event
    event = self._extract_next_receive_event()
  File "/data1/work/.conda/envs/nlp/lib/python3.8/site-packages/h11/_connection.py", line 367, in _extract_next_receive_event
    event = self._reader(self._receive_buffer)
  File "/data1/work/.conda/envs/nlp/lib/python3.8/site-packages/h11/_readers.py", line 68, in maybe_read_from_IDLE_client
    raise LocalProtocolError("illegal request line")
h11._util.RemoteProtocolError: illegal request line
2022-05-18 18:22:15,753, WARNING Invalid HTTP request received.
Traceback (most recent call last):
  File "/data1/work/.conda/envs/nlp/lib/python3.8/site-packages/uvicorn/protocols/http/h11_impl.py", line 129, in handle_events
    event = self.conn.next_event()
  File "/data1/work/.conda/envs/nlp/lib/python3.8/site-packages/h11/_connection.py", line 443, in next_event
    exc._reraise_as_remote_protocol_error()
  File "/data1/work/.conda/envs/nlp/lib/python3.8/site-packages/h11/_util.py", line 76, in _reraise_as_remote_protocol_error
    raise self
  File "/data1/work/.conda/envs/nlp/lib/python3.8/site-packages/h11/_connection.py", line 425, in next_event
    event = self._extract_next_receive_event()
  File "/data1/work/.conda/envs/nlp/lib/python3.8/site-packages/h11/_connection.py", line 367, in _extract_next_receive_event
    event = self._reader(self._receive_buffer)
  File "/data1/work/.conda/envs/nlp/lib/python3.8/site-packages/h11/_readers.py", line 68, in maybe_read_from_IDLE_client
    raise LocalProtocolError("illegal request line")
h11._util.RemoteProtocolError: illegal request line
2022-05-18 18:22:16,413, WARNING Invalid HTTP request received.
Traceback (most recent call last):
  File "/data1/work/.conda/envs/nlp/lib/python3.8/site-packages/uvicorn/protocols/http/h11_impl.py", line 129, in handle_events
    event = self.conn.next_event()
  File "/data1/work/.conda/envs/nlp/lib/python3.8/site-packages/h11/_connection.py", line 443, in next_event
    exc._reraise_as_remote_protocol_error()
  File "/data1/work/.conda/envs/nlp/lib/python3.8/site-packages/h11/_util.py", line 76, in _reraise_as_remote_protocol_error
    raise self
  File "/data1/work/.conda/envs/nlp/lib/python3.8/site-packages/h11/_connection.py", line 425, in next_event
    event = self._extract_next_receive_event()
  File "/data1/work/.conda/envs/nlp/lib/python3.8/site-packages/h11/_connection.py", line 367, in _extract_next_receive_event
    event = self._reader(self._receive_buffer)
  File "/data1/work/.conda/envs/nlp/lib/python3.8/site-packages/h11/_readers.py", line 68, in maybe_read_from_IDLE_client
    raise LocalProtocolError("illegal request line")
h11._util.RemoteProtocolError: illegal request line
2022-05-18 18:22:17,217, WARNING Invalid HTTP request received.
Traceback (most recent call last):
  File "/data1/work/.conda/envs/nlp/lib/python3.8/site-packages/uvicorn/protocols/http/h11_impl.py", line 129, in handle_events
    event = self.conn.next_event()
  File "/data1/work/.conda/envs/nlp/lib/python3.8/site-packages/h11/_connection.py", line 443, in next_event
    exc._reraise_as_remote_protocol_error()
  File "/data1/work/.conda/envs/nlp/lib/python3.8/site-packages/h11/_util.py", line 76, in _reraise_as_remote_protocol_error
    raise self
  File "/data1/work/.conda/envs/nlp/lib/python3.8/site-packages/h11/_connection.py", line 425, in next_event
    event = self._extract_next_receive_event()
  File "/data1/work/.conda/envs/nlp/lib/python3.8/site-packages/h11/_connection.py", line 367, in _extract_next_receive_event
    event = self._reader(self._receive_buffer)
  File "/data1/work/.conda/envs/nlp/lib/python3.8/site-packages/h11/_readers.py", line 68, in maybe_read_from_IDLE_client
    raise LocalProtocolError("illegal request line")
h11._util.RemoteProtocolError: illegal request line
2022-05-18 18:22:17,900, WARNING Invalid HTTP request received.
Traceback (most recent call last):
  File "/data1/work/.conda/envs/nlp/lib/python3.8/site-packages/uvicorn/protocols/http/h11_impl.py", line 129, in handle_events
    event = self.conn.next_event()
  File "/data1/work/.conda/envs/nlp/lib/python3.8/site-packages/h11/_connection.py", line 443, in next_event
    exc._reraise_as_remote_protocol_error()
  File "/data1/work/.conda/envs/nlp/lib/python3.8/site-packages/h11/_util.py", line 76, in _reraise_as_remote_protocol_error
    raise self
  File "/data1/work/.conda/envs/nlp/lib/python3.8/site-packages/h11/_connection.py", line 425, in next_event
    event = self._extract_next_receive_event()
  File "/data1/work/.conda/envs/nlp/lib/python3.8/site-packages/h11/_connection.py", line 367, in _extract_next_receive_event
    event = self._reader(self._receive_buffer)
  File "/data1/work/.conda/envs/nlp/lib/python3.8/site-packages/h11/_readers.py", line 68, in maybe_read_from_IDLE_client
    raise LocalProtocolError("illegal request line")
h11._util.RemoteProtocolError: illegal request line
2022-05-18 18:22:23,912, WARNING Invalid HTTP request received.
Traceback (most recent call last):
  File "/data1/work/.conda/envs/nlp/lib/python3.8/site-packages/uvicorn/protocols/http/h11_impl.py", line 129, in handle_events
    event = self.conn.next_event()
  File "/data1/work/.conda/envs/nlp/lib/python3.8/site-packages/h11/_connection.py", line 443, in next_event
    exc._reraise_as_remote_protocol_error()
  File "/data1/work/.conda/envs/nlp/lib/python3.8/site-packages/h11/_util.py", line 76, in _reraise_as_remote_protocol_error
    raise self
  File "/data1/work/.conda/envs/nlp/lib/python3.8/site-packages/h11/_connection.py", line 425, in next_event
    event = self._extract_next_receive_event()
  File "/data1/work/.conda/envs/nlp/lib/python3.8/site-packages/h11/_connection.py", line 367, in _extract_next_receive_event
    event = self._reader(self._receive_buffer)
  File "/data1/work/.conda/envs/nlp/lib/python3.8/site-packages/h11/_readers.py", line 72, in maybe_read_from_IDLE_client
    matches = validate(
  File "/data1/work/.conda/envs/nlp/lib/python3.8/site-packages/h11/_util.py", line 88, in validate
    raise LocalProtocolError(msg)
h11._util.RemoteProtocolError: illegal request line: bytearray(b'OPTIONS sip:nm SIP/2.0')
2022-05-18 18:22:27,139, WARNING Invalid HTTP request received.
Traceback (most recent call last):
  File "/data1/work/.conda/envs/nlp/lib/python3.8/site-packages/uvicorn/protocols/http/h11_impl.py", line 129, in handle_events
    event = self.conn.next_event()
  File "/data1/work/.conda/envs/nlp/lib/python3.8/site-packages/h11/_connection.py", line 443, in next_event
    exc._reraise_as_remote_protocol_error()
  File "/data1/work/.conda/envs/nlp/lib/python3.8/site-packages/h11/_util.py", line 76, in _reraise_as_remote_protocol_error
    raise self
  File "/data1/work/.conda/envs/nlp/lib/python3.8/site-packages/h11/_connection.py", line 425, in next_event
    event = self._extract_next_receive_event()
  File "/data1/work/.conda/envs/nlp/lib/python3.8/site-packages/h11/_connection.py", line 367, in _extract_next_receive_event
    event = self._reader(self._receive_buffer)
  File "/data1/work/.conda/envs/nlp/lib/python3.8/site-packages/h11/_readers.py", line 68, in maybe_read_from_IDLE_client
    raise LocalProtocolError("illegal request line")
h11._util.RemoteProtocolError: illegal request line
2022-05-18 18:22:27,724, WARNING Invalid HTTP request received.
Traceback (most recent call last):
  File "/data1/work/.conda/envs/nlp/lib/python3.8/site-packages/uvicorn/protocols/http/h11_impl.py", line 129, in handle_events
    event = self.conn.next_event()
  File "/data1/work/.conda/envs/nlp/lib/python3.8/site-packages/h11/_connection.py", line 443, in next_event
    exc._reraise_as_remote_protocol_error()
  File "/data1/work/.conda/envs/nlp/lib/python3.8/site-packages/h11/_util.py", line 76, in _reraise_as_remote_protocol_error
    raise self
  File "/data1/work/.conda/envs/nlp/lib/python3.8/site-packages/h11/_connection.py", line 425, in next_event
    event = self._extract_next_receive_event()
  File "/data1/work/.conda/envs/nlp/lib/python3.8/site-packages/h11/_connection.py", line 367, in _extract_next_receive_event
    event = self._reader(self._receive_buffer)
  File "/data1/work/.conda/envs/nlp/lib/python3.8/site-packages/h11/_readers.py", line 68, in maybe_read_from_IDLE_client
    raise LocalProtocolError("illegal request line")
h11._util.RemoteProtocolError: illegal request line
2022-05-18 18:22:37,522, WARNING Invalid HTTP request received.
Traceback (most recent call last):
  File "/data1/work/.conda/envs/nlp/lib/python3.8/site-packages/uvicorn/protocols/http/h11_impl.py", line 129, in handle_events
    event = self.conn.next_event()
  File "/data1/work/.conda/envs/nlp/lib/python3.8/site-packages/h11/_connection.py", line 443, in next_event
    exc._reraise_as_remote_protocol_error()
  File "/data1/work/.conda/envs/nlp/lib/python3.8/site-packages/h11/_util.py", line 76, in _reraise_as_remote_protocol_error
    raise self
  File "/data1/work/.conda/envs/nlp/lib/python3.8/site-packages/h11/_connection.py", line 425, in next_event
    event = self._extract_next_receive_event()
  File "/data1/work/.conda/envs/nlp/lib/python3.8/site-packages/h11/_connection.py", line 367, in _extract_next_receive_event
    event = self._reader(self._receive_buffer)
  File "/data1/work/.conda/envs/nlp/lib/python3.8/site-packages/h11/_readers.py", line 68, in maybe_read_from_IDLE_client
    raise LocalProtocolError("illegal request line")
h11._util.RemoteProtocolError: illegal request line
2022-05-18 19:52:09,828, WARNING Invalid HTTP request received.
Traceback (most recent call last):
  File "/data1/work/.conda/envs/nlp/lib/python3.8/site-packages/uvicorn/protocols/http/h11_impl.py", line 129, in handle_events
    event = self.conn.next_event()
  File "/data1/work/.conda/envs/nlp/lib/python3.8/site-packages/h11/_connection.py", line 443, in next_event
    exc._reraise_as_remote_protocol_error()
  File "/data1/work/.conda/envs/nlp/lib/python3.8/site-packages/h11/_util.py", line 76, in _reraise_as_remote_protocol_error
    raise self
  File "/data1/work/.conda/envs/nlp/lib/python3.8/site-packages/h11/_connection.py", line 425, in next_event
    event = self._extract_next_receive_event()
  File "/data1/work/.conda/envs/nlp/lib/python3.8/site-packages/h11/_connection.py", line 367, in _extract_next_receive_event
    event = self._reader(self._receive_buffer)
  File "/data1/work/.conda/envs/nlp/lib/python3.8/site-packages/h11/_readers.py", line 68, in maybe_read_from_IDLE_client
    raise LocalProtocolError("illegal request line")
h11._util.RemoteProtocolError: illegal request line
2022-05-18 19:55:29,787, DEBUG Starting new HTTP connection (1): 127.0.0.1:8080
2022-05-18 19:55:33,068, DEBUG http://127.0.0.1:8080 "POST /api/v0/generate HTTP/1.1" 200 307
2022-05-18 19:56:28,989, WARNING Invalid HTTP request received.
Traceback (most recent call last):
  File "/data1/work/.conda/envs/nlp/lib/python3.8/site-packages/uvicorn/protocols/http/h11_impl.py", line 129, in handle_events
    event = self.conn.next_event()
  File "/data1/work/.conda/envs/nlp/lib/python3.8/site-packages/h11/_connection.py", line 443, in next_event
    exc._reraise_as_remote_protocol_error()
  File "/data1/work/.conda/envs/nlp/lib/python3.8/site-packages/h11/_util.py", line 76, in _reraise_as_remote_protocol_error
    raise self
  File "/data1/work/.conda/envs/nlp/lib/python3.8/site-packages/h11/_connection.py", line 425, in next_event
    event = self._extract_next_receive_event()
  File "/data1/work/.conda/envs/nlp/lib/python3.8/site-packages/h11/_connection.py", line 367, in _extract_next_receive_event
    event = self._reader(self._receive_buffer)
  File "/data1/work/.conda/envs/nlp/lib/python3.8/site-packages/h11/_readers.py", line 68, in maybe_read_from_IDLE_client
    raise LocalProtocolError("illegal request line")
h11._util.RemoteProtocolError: illegal request line
2022-05-18 19:56:33,196, WARNING Invalid HTTP request received.
Traceback (most recent call last):
  File "/data1/work/.conda/envs/nlp/lib/python3.8/site-packages/uvicorn/protocols/http/h11_impl.py", line 129, in handle_events
    event = self.conn.next_event()
  File "/data1/work/.conda/envs/nlp/lib/python3.8/site-packages/h11/_connection.py", line 443, in next_event
    exc._reraise_as_remote_protocol_error()
  File "/data1/work/.conda/envs/nlp/lib/python3.8/site-packages/h11/_util.py", line 76, in _reraise_as_remote_protocol_error
    raise self
  File "/data1/work/.conda/envs/nlp/lib/python3.8/site-packages/h11/_connection.py", line 425, in next_event
    event = self._extract_next_receive_event()
  File "/data1/work/.conda/envs/nlp/lib/python3.8/site-packages/h11/_connection.py", line 367, in _extract_next_receive_event
    event = self._reader(self._receive_buffer)
  File "/data1/work/.conda/envs/nlp/lib/python3.8/site-packages/h11/_readers.py", line 68, in maybe_read_from_IDLE_client
    raise LocalProtocolError("illegal request line")
h11._util.RemoteProtocolError: illegal request line
2022-05-18 19:56:44,845, DEBUG Starting new HTTP connection (1): 127.0.0.1:8080
2022-05-18 19:56:48,133, DEBUG http://127.0.0.1:8080 "POST /api/v0/generate HTTP/1.1" 200 270
2022-05-18 19:58:03,649, WARNING Invalid HTTP request received.
Traceback (most recent call last):
  File "/data1/work/.conda/envs/nlp/lib/python3.8/site-packages/uvicorn/protocols/http/h11_impl.py", line 129, in handle_events
    event = self.conn.next_event()
  File "/data1/work/.conda/envs/nlp/lib/python3.8/site-packages/h11/_connection.py", line 443, in next_event
    exc._reraise_as_remote_protocol_error()
  File "/data1/work/.conda/envs/nlp/lib/python3.8/site-packages/h11/_util.py", line 76, in _reraise_as_remote_protocol_error
    raise self
  File "/data1/work/.conda/envs/nlp/lib/python3.8/site-packages/h11/_connection.py", line 425, in next_event
    event = self._extract_next_receive_event()
  File "/data1/work/.conda/envs/nlp/lib/python3.8/site-packages/h11/_connection.py", line 367, in _extract_next_receive_event
    event = self._reader(self._receive_buffer)
  File "/data1/work/.conda/envs/nlp/lib/python3.8/site-packages/h11/_readers.py", line 68, in maybe_read_from_IDLE_client
    raise LocalProtocolError("illegal request line")
h11._util.RemoteProtocolError: illegal request line
2022-05-18 21:39:11,311, WARNING Invalid HTTP request received.
Traceback (most recent call last):
  File "/data1/work/.conda/envs/nlp/lib/python3.8/site-packages/uvicorn/protocols/http/h11_impl.py", line 129, in handle_events
    event = self.conn.next_event()
  File "/data1/work/.conda/envs/nlp/lib/python3.8/site-packages/h11/_connection.py", line 443, in next_event
    exc._reraise_as_remote_protocol_error()
  File "/data1/work/.conda/envs/nlp/lib/python3.8/site-packages/h11/_util.py", line 76, in _reraise_as_remote_protocol_error
    raise self
  File "/data1/work/.conda/envs/nlp/lib/python3.8/site-packages/h11/_connection.py", line 425, in next_event
    event = self._extract_next_receive_event()
  File "/data1/work/.conda/envs/nlp/lib/python3.8/site-packages/h11/_connection.py", line 367, in _extract_next_receive_event
    event = self._reader(self._receive_buffer)
  File "/data1/work/.conda/envs/nlp/lib/python3.8/site-packages/h11/_readers.py", line 68, in maybe_read_from_IDLE_client
    raise LocalProtocolError("illegal request line")
h11._util.RemoteProtocolError: illegal request line
