2022-05-04 05:42:15,534, WARNING Invalid HTTP request received.
Traceback (most recent call last):
  File "/data1/work/.conda/envs/nlp/lib/python3.8/site-packages/uvicorn/protocols/http/h11_impl.py", line 129, in handle_events
    event = self.conn.next_event()
  File "/data1/work/.conda/envs/nlp/lib/python3.8/site-packages/h11/_connection.py", line 443, in next_event
    exc._reraise_as_remote_protocol_error()
  File "/data1/work/.conda/envs/nlp/lib/python3.8/site-packages/h11/_util.py", line 76, in _reraise_as_remote_protocol_error
    raise self
  File "/data1/work/.conda/envs/nlp/lib/python3.8/site-packages/h11/_connection.py", line 425, in next_event
    event = self._extract_next_receive_event()
  File "/data1/work/.conda/envs/nlp/lib/python3.8/site-packages/h11/_connection.py", line 367, in _extract_next_receive_event
    event = self._reader(self._receive_buffer)
  File "/data1/work/.conda/envs/nlp/lib/python3.8/site-packages/h11/_readers.py", line 68, in maybe_read_from_IDLE_client
    raise LocalProtocolError("illegal request line")
h11._util.RemoteProtocolError: illegal request line
2022-05-04 05:42:20,914, WARNING Invalid HTTP request received.
Traceback (most recent call last):
  File "/data1/work/.conda/envs/nlp/lib/python3.8/site-packages/uvicorn/protocols/http/h11_impl.py", line 129, in handle_events
    event = self.conn.next_event()
  File "/data1/work/.conda/envs/nlp/lib/python3.8/site-packages/h11/_connection.py", line 443, in next_event
    exc._reraise_as_remote_protocol_error()
  File "/data1/work/.conda/envs/nlp/lib/python3.8/site-packages/h11/_util.py", line 76, in _reraise_as_remote_protocol_error
    raise self
  File "/data1/work/.conda/envs/nlp/lib/python3.8/site-packages/h11/_connection.py", line 425, in next_event
    event = self._extract_next_receive_event()
  File "/data1/work/.conda/envs/nlp/lib/python3.8/site-packages/h11/_connection.py", line 367, in _extract_next_receive_event
    event = self._reader(self._receive_buffer)
  File "/data1/work/.conda/envs/nlp/lib/python3.8/site-packages/h11/_readers.py", line 68, in maybe_read_from_IDLE_client
    raise LocalProtocolError("illegal request line")
h11._util.RemoteProtocolError: illegal request line
2022-05-04 05:42:23,521, WARNING Invalid HTTP request received.
Traceback (most recent call last):
  File "/data1/work/.conda/envs/nlp/lib/python3.8/site-packages/uvicorn/protocols/http/h11_impl.py", line 129, in handle_events
    event = self.conn.next_event()
  File "/data1/work/.conda/envs/nlp/lib/python3.8/site-packages/h11/_connection.py", line 443, in next_event
    exc._reraise_as_remote_protocol_error()
  File "/data1/work/.conda/envs/nlp/lib/python3.8/site-packages/h11/_util.py", line 76, in _reraise_as_remote_protocol_error
    raise self
  File "/data1/work/.conda/envs/nlp/lib/python3.8/site-packages/h11/_connection.py", line 425, in next_event
    event = self._extract_next_receive_event()
  File "/data1/work/.conda/envs/nlp/lib/python3.8/site-packages/h11/_connection.py", line 367, in _extract_next_receive_event
    event = self._reader(self._receive_buffer)
  File "/data1/work/.conda/envs/nlp/lib/python3.8/site-packages/h11/_readers.py", line 72, in maybe_read_from_IDLE_client
    matches = validate(
  File "/data1/work/.conda/envs/nlp/lib/python3.8/site-packages/h11/_util.py", line 88, in validate
    raise LocalProtocolError(msg)
h11._util.RemoteProtocolError: illegal request line: bytearray(b'SM')
2022-05-04 09:43:44,817, WARNING Invalid HTTP request received.
Traceback (most recent call last):
  File "/data1/work/.conda/envs/nlp/lib/python3.8/site-packages/uvicorn/protocols/http/h11_impl.py", line 129, in handle_events
    event = self.conn.next_event()
  File "/data1/work/.conda/envs/nlp/lib/python3.8/site-packages/h11/_connection.py", line 443, in next_event
    exc._reraise_as_remote_protocol_error()
  File "/data1/work/.conda/envs/nlp/lib/python3.8/site-packages/h11/_util.py", line 76, in _reraise_as_remote_protocol_error
    raise self
  File "/data1/work/.conda/envs/nlp/lib/python3.8/site-packages/h11/_connection.py", line 425, in next_event
    event = self._extract_next_receive_event()
  File "/data1/work/.conda/envs/nlp/lib/python3.8/site-packages/h11/_connection.py", line 367, in _extract_next_receive_event
    event = self._reader(self._receive_buffer)
  File "/data1/work/.conda/envs/nlp/lib/python3.8/site-packages/h11/_readers.py", line 68, in maybe_read_from_IDLE_client
    raise LocalProtocolError("illegal request line")
h11._util.RemoteProtocolError: illegal request line
2022-05-04 09:56:18,491, DEBUG Starting new HTTP connection (1): 127.0.0.1:8080
2022-05-04 09:56:20,549, DEBUG http://127.0.0.1:8080 "POST /api/v0/generate HTTP/1.1" 200 336
2022-05-04 10:15:08,472, WARNING Invalid HTTP request received.
Traceback (most recent call last):
  File "/data1/work/.conda/envs/nlp/lib/python3.8/site-packages/uvicorn/protocols/http/h11_impl.py", line 129, in handle_events
    event = self.conn.next_event()
  File "/data1/work/.conda/envs/nlp/lib/python3.8/site-packages/h11/_connection.py", line 443, in next_event
    exc._reraise_as_remote_protocol_error()
  File "/data1/work/.conda/envs/nlp/lib/python3.8/site-packages/h11/_util.py", line 76, in _reraise_as_remote_protocol_error
    raise self
  File "/data1/work/.conda/envs/nlp/lib/python3.8/site-packages/h11/_connection.py", line 425, in next_event
    event = self._extract_next_receive_event()
  File "/data1/work/.conda/envs/nlp/lib/python3.8/site-packages/h11/_connection.py", line 367, in _extract_next_receive_event
    event = self._reader(self._receive_buffer)
  File "/data1/work/.conda/envs/nlp/lib/python3.8/site-packages/h11/_readers.py", line 68, in maybe_read_from_IDLE_client
    raise LocalProtocolError("illegal request line")
h11._util.RemoteProtocolError: illegal request line
2022-05-04 10:15:13,965, WARNING Invalid HTTP request received.
Traceback (most recent call last):
  File "/data1/work/.conda/envs/nlp/lib/python3.8/site-packages/uvicorn/protocols/http/h11_impl.py", line 129, in handle_events
    event = self.conn.next_event()
  File "/data1/work/.conda/envs/nlp/lib/python3.8/site-packages/h11/_connection.py", line 443, in next_event
    exc._reraise_as_remote_protocol_error()
  File "/data1/work/.conda/envs/nlp/lib/python3.8/site-packages/h11/_util.py", line 76, in _reraise_as_remote_protocol_error
    raise self
  File "/data1/work/.conda/envs/nlp/lib/python3.8/site-packages/h11/_connection.py", line 425, in next_event
    event = self._extract_next_receive_event()
  File "/data1/work/.conda/envs/nlp/lib/python3.8/site-packages/h11/_connection.py", line 367, in _extract_next_receive_event
    event = self._reader(self._receive_buffer)
  File "/data1/work/.conda/envs/nlp/lib/python3.8/site-packages/h11/_readers.py", line 68, in maybe_read_from_IDLE_client
    raise LocalProtocolError("illegal request line")
h11._util.RemoteProtocolError: illegal request line
2022-05-04 10:15:17,490, WARNING Invalid HTTP request received.
Traceback (most recent call last):
  File "/data1/work/.conda/envs/nlp/lib/python3.8/site-packages/uvicorn/protocols/http/h11_impl.py", line 129, in handle_events
    event = self.conn.next_event()
  File "/data1/work/.conda/envs/nlp/lib/python3.8/site-packages/h11/_connection.py", line 443, in next_event
    exc._reraise_as_remote_protocol_error()
  File "/data1/work/.conda/envs/nlp/lib/python3.8/site-packages/h11/_util.py", line 76, in _reraise_as_remote_protocol_error
    raise self
  File "/data1/work/.conda/envs/nlp/lib/python3.8/site-packages/h11/_connection.py", line 425, in next_event
    event = self._extract_next_receive_event()
  File "/data1/work/.conda/envs/nlp/lib/python3.8/site-packages/h11/_connection.py", line 367, in _extract_next_receive_event
    event = self._reader(self._receive_buffer)
  File "/data1/work/.conda/envs/nlp/lib/python3.8/site-packages/h11/_readers.py", line 72, in maybe_read_from_IDLE_client
    matches = validate(
  File "/data1/work/.conda/envs/nlp/lib/python3.8/site-packages/h11/_util.py", line 88, in validate
    raise LocalProtocolError(msg)
h11._util.RemoteProtocolError: illegal request line: bytearray(b'SM')
2022-05-04 11:13:49,371, DEBUG Starting new HTTP connection (1): 127.0.0.1:8080
2022-05-04 11:13:51,438, DEBUG http://127.0.0.1:8080 "POST /api/v0/generate HTTP/1.1" 200 261
2022-05-04 11:14:26,314, DEBUG Starting new HTTP connection (1): 127.0.0.1:8080
2022-05-04 11:14:28,376, DEBUG http://127.0.0.1:8080 "POST /api/v0/generate HTTP/1.1" 200 158
2022-05-04 11:14:49,144, DEBUG Starting new HTTP connection (1): 127.0.0.1:8080
2022-05-04 11:14:51,200, DEBUG http://127.0.0.1:8080 "POST /api/v0/generate HTTP/1.1" 200 284
2022-05-04 11:15:39,718, DEBUG Starting new HTTP connection (1): 127.0.0.1:8080
2022-05-04 11:15:41,653, DEBUG http://127.0.0.1:8080 "POST /api/v0/generate HTTP/1.1" 200 210
2022-05-04 11:15:44,160, DEBUG Starting new HTTP connection (1): 127.0.0.1:8080
2022-05-04 11:15:46,202, DEBUG http://127.0.0.1:8080 "POST /api/v0/generate HTTP/1.1" 200 323
2022-05-04 11:16:27,429, DEBUG Starting new HTTP connection (1): 127.0.0.1:8080
2022-05-04 11:16:29,491, DEBUG http://127.0.0.1:8080 "POST /api/v0/generate HTTP/1.1" 200 270
2022-05-04 11:18:59,663, DEBUG Starting new HTTP connection (1): 127.0.0.1:8080
2022-05-04 11:19:01,017, DEBUG http://127.0.0.1:8080 "POST /api/v0/generate HTTP/1.1" 200 221
2022-05-04 12:23:53,448, WARNING Invalid HTTP request received.
Traceback (most recent call last):
  File "/data1/work/.conda/envs/nlp/lib/python3.8/site-packages/uvicorn/protocols/http/h11_impl.py", line 129, in handle_events
    event = self.conn.next_event()
  File "/data1/work/.conda/envs/nlp/lib/python3.8/site-packages/h11/_connection.py", line 443, in next_event
    exc._reraise_as_remote_protocol_error()
  File "/data1/work/.conda/envs/nlp/lib/python3.8/site-packages/h11/_util.py", line 76, in _reraise_as_remote_protocol_error
    raise self
  File "/data1/work/.conda/envs/nlp/lib/python3.8/site-packages/h11/_connection.py", line 425, in next_event
    event = self._extract_next_receive_event()
  File "/data1/work/.conda/envs/nlp/lib/python3.8/site-packages/h11/_connection.py", line 367, in _extract_next_receive_event
    event = self._reader(self._receive_buffer)
  File "/data1/work/.conda/envs/nlp/lib/python3.8/site-packages/h11/_readers.py", line 68, in maybe_read_from_IDLE_client
    raise LocalProtocolError("illegal request line")
h11._util.RemoteProtocolError: illegal request line
2022-05-04 14:34:28,079, WARNING Invalid HTTP request received.
Traceback (most recent call last):
  File "/data1/work/.conda/envs/nlp/lib/python3.8/site-packages/uvicorn/protocols/http/h11_impl.py", line 129, in handle_events
    event = self.conn.next_event()
  File "/data1/work/.conda/envs/nlp/lib/python3.8/site-packages/h11/_connection.py", line 443, in next_event
    exc._reraise_as_remote_protocol_error()
  File "/data1/work/.conda/envs/nlp/lib/python3.8/site-packages/h11/_util.py", line 76, in _reraise_as_remote_protocol_error
    raise self
  File "/data1/work/.conda/envs/nlp/lib/python3.8/site-packages/h11/_connection.py", line 425, in next_event
    event = self._extract_next_receive_event()
  File "/data1/work/.conda/envs/nlp/lib/python3.8/site-packages/h11/_connection.py", line 367, in _extract_next_receive_event
    event = self._reader(self._receive_buffer)
  File "/data1/work/.conda/envs/nlp/lib/python3.8/site-packages/h11/_readers.py", line 68, in maybe_read_from_IDLE_client
    raise LocalProtocolError("illegal request line")
h11._util.RemoteProtocolError: illegal request line
2022-05-04 14:57:15,676, INFO Shutting down
2022-05-04 14:57:15,777, INFO Waiting for application shutdown.
2022-05-04 14:57:15,779, INFO Application shutdown complete.
2022-05-04 14:57:15,779, INFO Finished server process [627431]
